{
 "cells": [
  {
   "cell_type": "markdown",
   "id": "58a05562",
   "metadata": {},
   "source": [
    "# Fake News Detection\n",
    "\n"
   ]
  },
  {
   "cell_type": "markdown",
   "id": "e3e78b17",
   "metadata": {},
   "source": [
    "#### Import library"
   ]
  },
  {
   "cell_type": "code",
   "execution_count": 1,
   "id": "9f265927",
   "metadata": {},
   "outputs": [
    {
     "ename": "ModuleNotFoundError",
     "evalue": "No module named 'pandas'",
     "output_type": "error",
     "traceback": [
      "\u001b[1;31m---------------------------------------------------------------------------\u001b[0m",
      "\u001b[1;31mModuleNotFoundError\u001b[0m                       Traceback (most recent call last)",
      "Cell \u001b[1;32mIn[1], line 1\u001b[0m\n\u001b[1;32m----> 1\u001b[0m \u001b[38;5;28;01mimport\u001b[39;00m \u001b[38;5;21;01mpandas\u001b[39;00m \u001b[38;5;28;01mas\u001b[39;00m \u001b[38;5;21;01mpd\u001b[39;00m\n\u001b[0;32m      2\u001b[0m \u001b[38;5;28;01mimport\u001b[39;00m \u001b[38;5;21;01mnumpy\u001b[39;00m \u001b[38;5;28;01mas\u001b[39;00m \u001b[38;5;21;01mnp\u001b[39;00m\n",
      "\u001b[1;31mModuleNotFoundError\u001b[0m: No module named 'pandas'"
     ]
    }
   ],
   "source": [
    "import pandas as pd\n",
    "import numpy as np\n",
    "import itertools\n"
   ]
  },
  {
   "cell_type": "code",
   "execution_count": 3,
   "id": "365c3386",
   "metadata": {},
   "outputs": [
    {
     "name": "stdout",
     "output_type": "stream",
     "text": [
      "Requirement already satisfied: pandas in c:\\users\\admin\\appdata\\local\\programs\\python\\python311\\lib\\site-packages (2.0.1)\n",
      "Requirement already satisfied: python-dateutil>=2.8.2 in c:\\users\\admin\\appdata\\local\\programs\\python\\python311\\lib\\site-packages (from pandas) (2.8.2)\n",
      "Requirement already satisfied: pytz>=2020.1 in c:\\users\\admin\\appdata\\local\\programs\\python\\python311\\lib\\site-packages (from pandas) (2023.3)\n",
      "Requirement already satisfied: tzdata>=2022.1 in c:\\users\\admin\\appdata\\local\\programs\\python\\python311\\lib\\site-packages (from pandas) (2023.3)\n",
      "Requirement already satisfied: numpy>=1.21.0 in c:\\users\\admin\\appdata\\local\\programs\\python\\python311\\lib\\site-packages (from pandas) (1.24.3)\n",
      "Requirement already satisfied: six>=1.5 in c:\\users\\admin\\appdata\\local\\programs\\python\\python311\\lib\\site-packages (from python-dateutil>=2.8.2->pandas) (1.16.0)\n"
     ]
    }
   ],
   "source": [
    "!pip install pandas\n"
   ]
  },
  {
   "cell_type": "code",
   "execution_count": 4,
   "id": "e0b0ae13",
   "metadata": {},
   "outputs": [
    {
     "ename": "NameError",
     "evalue": "name 'pd' is not defined",
     "output_type": "error",
     "traceback": [
      "\u001b[1;31m---------------------------------------------------------------------------\u001b[0m",
      "\u001b[1;31mNameError\u001b[0m                                 Traceback (most recent call last)",
      "Cell \u001b[1;32mIn[4], line 1\u001b[0m\n\u001b[1;32m----> 1\u001b[0m df \u001b[38;5;241m=\u001b[39m \u001b[43mpd\u001b[49m\u001b[38;5;241m.\u001b[39mread_csv(\u001b[38;5;124m\"\u001b[39m\u001b[38;5;124mnews.csv\u001b[39m\u001b[38;5;124m\"\u001b[39m)\n",
      "\u001b[1;31mNameError\u001b[0m: name 'pd' is not defined"
     ]
    }
   ],
   "source": [
    "df = pd.read_csv(\"news.csv\")"
   ]
  },
  {
   "cell_type": "code",
   "execution_count": null,
   "id": "8851c9fd",
   "metadata": {},
   "outputs": [],
   "source": []
  }
 ],
 "metadata": {
  "kernelspec": {
   "display_name": "Python 3 (ipykernel)",
   "language": "python",
   "name": "python3"
  },
  "language_info": {
   "codemirror_mode": {
    "name": "ipython",
    "version": 3
   },
   "file_extension": ".py",
   "mimetype": "text/x-python",
   "name": "python",
   "nbconvert_exporter": "python",
   "pygments_lexer": "ipython3",
   "version": "3.11.3"
  }
 },
 "nbformat": 4,
 "nbformat_minor": 5
}
